// exemplo do conteúdo "expect e matchers"

const multiplyByTwo = require('./testingExcecao');

test('testa se multiplyByTwo retorna o resultado da multiplicação', () => {
  expect(multiplyByTwo(4)).toBe(8);
});
test('testa se é lançado um erro quando number é indefinido', () => {
  expect(() => { multiplyByTwo() }).toThrow();
});
test('testa se a mensagem de erro é "number é indefinido"', () => {
  expect(() => { multiplyByTwo() }).toThrowError(new Error('number é indefinido'));
});

//Note que para testar se um erro é lançado, passamos para o expect uma função. Chamamos multiplyByTwo dentro da arrow function . Chamar a função diretamente dentro de expect fará com que o erro não seja capturado. Assim, a asserção falhará, porque o erro acontecerá antes mesmo de expect ser executado e ter a chance de capturar o erro. Para testar a mensagem de erro, como fizemos no terceiro teste do exemplo acima, usamos o matcher toThrowError e passamos dentro do parênteses a mensagem que será mostrada em caso de erro: new Error("number é indefinido") . Observe que nos dois casos a função que queremos testar é chamada indiretamente por uma arrow function . Seguir essa sintaxe é importante para que o seu teste funcione corretamente.